Workbook

Sheet Overall
A1: Balance Sheet
A3: Mã số | B3: Chỉ tiêu | C3: 2022 | D3: 2023 | E3: 2024 | F3: 2025
A4: 100 | B4: TÀI SẢN NGẮN HẠN | C4: 55651707958020 | D4: 62217752152930 | E4: 57290495430038 | F4: 69902465635326
A5: 110 | B5: Tiền và các khoản tương đương tiền | C5: 10549337638537 | D5: 5668895193049 | E5: 5567983431468 | F5: 6876468282085
A6: 111 | B6: Tiền | C6: 1318137638537 | D6: 1156470360119 | E6: 1248083431468 | F6: 913368282085
A7: 112 | B7: Các khoản tương đương tiền | C7: 9231200000000 | D7: 4512424832930 | E7: 4319900000000 | F7: 5963100000000
A8: 120 | B8: Khoản đầu tư tài chính ngắn hạn | C8: 23726498790237 | D8: 35084645516061 | E8: 27404031282702 | F8: 32890551400598
A9: 123 | B9: Đầu tư nắm giữ đến ngày đáo hạn | C9: 23726498790237 | D9: 35084645516061 | E9: 27404031282702 | F9: 32890551400598
A10: 130 | B10: Các khoản phải thu ngắn hạn | C10: 16191131770955 | D10: 16865314290394 | E10: 19098417078475 | F10: 24881281586057
A11: 131 | B11: Phải thu ngắn hạn của khách hàng | C11: 9210085888347 | D11: 12541281232880 | E11: 16744655874477 | F11: 20895137507650
A12: 132 | B12: Trả trước cho người bán ngắn hạn | C12: 223750541755 | D12: 264140292943 | E12: 375639323197 | F12: 116028764094
A13: 136 | B13: Phải thu ngắn hạn khác | C13: 7492404206264 | D13: 4910282039910 | E13: 4746916152558 | F13: 6202355202674
A14: 137 | B14: Dự phòng phải thu ngắn hạn khó đòi | C14: -737052792533 | D14: -850389329339 | E14: -768794271757 | F14: -2332239888361
A15: 139 | B15: Tài sản thiếu chờ xử lý | C15: 1943927122 | D15: - | E15: -
A16: 140 | B16: Hàng tồn kho | C16: 4102441805643 | D16: 3944544425746 | E16: 4598950949693 | F16: 4398771281185
A17: 141 | B17: Hàng tồn kho | C17: 4185337349642 | D17: 4069874528094 | E17: 4732006717115 | F17: 4587524289258
A18: 149 | B18: Dự phòng giảm giá hàng tồn kho | C18: -82895543999 | D18: -125330102348 | E18: -133055767522 | F18: -188753008073
A19: 150 | B19: Tài sản ngắn hạn khác | C19: 1082297952648 | D19: 654352727689 | E19: 531112687800 | F19: 855393085401
A20: 151 | B20: Chi phí trả trước ngắn hạn | C20: 83670910085 | D20: 60533414354 | E20: 46023323039 | F20: 67084167708
A21: 152 | B21: Thuế GTGT được khấu trừ | C21: 949414975835 | D21: 547765432305 | E21: 447768536836 | F21: 678451569696
A22: 153 | B22: Thuế và các khoản phải thu Nhà nước | C22: 49212066728 | D22: 46053881030 | E22: 37320827925 | F22: 109857347997
A23: 200 | B23: TÀI SẢN DÀI HẠN | C23: 27010944408343 | D23: 25536703177509 | E23: 24564385978120 | F23: 23665732474464
A24: 210 | B24: Các khoản phải thu dài hạn | C24: 168689074161 | D24: 318104299805 | E24: 531249275544 | F24: 1123710993580
A25: 212 | B25: Trả trước cho người bán dài hạn | C25: 76326529951 | D25: 75492428136 | E25: 70495232935 | F25: 66106076719
A26: 216 | B26: Phải thu dài hạn khác | C26: 92362544210 | D26: 242611871669 | E26: 460754042609 | F26: 1057604916861
A27: 220 | B27: Tài sản cố định | C27: 16369664841026 | D27: 19532137951089 | E27: 18221636601588 | F27: 15950791009155
... A67: 411 | B67: Vốn góp của chủ sở hữu | C67: 19139500000000 | D67: 22967398470000 | E67: 23426729190000 | F67: 24129497560000
A68: 411a | B68: Cổ phiếu phổ thông có quyền biểu quyết | C68: 19139500000000 | D68: 22967398470000 | E68: 23426729190000 | F68: 24129497560000
A69: 412 | B69: Thặng dư vốn cổ phần | C69: 210679541297 | D69: 246727266 | E69: 246727266 | F69: 246727266
A70: 414 | B70: Vốn khác của chủ sở hữu | C70: 196658562648 | D70: 282322856474 | E70: 300272460670 | F70: 300272460670
A71: 418 | B71: Quỹ đầu tư phát triển | C71: 21063056727255 | D71: 23919001668407 | E71: 26967513791097 | F71: 29380604391166
A72: 420 | B72: Quỹ khác thuộc vốn chủ sở hữu | C72: 6287318113 | D72: - | E72: -
A73: 421 | B73: LNST chưa phân phối | C73: 19241492510616 | D73: 16879761088028 | E73: 9553019715422 | F73: 12484110062726
A74: 421a | B74: LNST chưa phân phối lũy kế | C74: 4601880959161 | D74: 5461127074863 | E74: -647086478241 | F74: 1277658070533
A75: 421b | B75: LNST chưa phân phối năm nay | C75: 14639611551455 | D75: 11418634013165 | E75: 10200106193663 | F75: 11212452052193
A76: 429 | B76: Lợi ích cổ đông không kiểm soát | C76: 1315888895212 | D76: 1249889464218 | E76: 1323213381181 | F76: 1358410438814
A77: 440 | B77: TỔNG NGUỒN VỐN | C77: 82662652366363 | D77: 87754455330448 | E77: 81854881408158 | F77: 93568198109790
A79: Income Statement
A80: Mã số | B80: Chỉ tiêu | C80: 2022 | D80: 2023 | E80: 2024 | F80: 2025
A81: 1 | B81: Doanh thu bán hàng và cung cấp dịch vụ | C81: 100723549227433 | D81: 90014136902542 | E81: 103603614927247 | F81: 135196548909363
...

Sheet Balance Sheet
A1: Balance Sheet
A2: All numbers in dong | B2: Tất cả số liệu tính theo đồng
C3: Mã số | D3: 2022 | E3: 2023 | F3: 2024 | G3: 2025
A4: Current Assets | B4: Tài sản ngắn hạn
A5: Cash And Cash Equivalents | B5: Tiền và các khoản tương đương tiền | C5: 110 | D5: =IFERROR(INDEX(Overall!$B$4:$F$77, MATCH('Balance Sheet'!$C5,Overall!$A$4:$A$77,0), MATCH('Balance Sheet'!D$3,Overall!$B$3:$F$3,0)),"") -> 10549337638537 | E5: =IFERROR(INDEX(Overall!$B$4:$F$77, MATCH('Balance Sheet'!$C5,Overall!$A$4:$A$77,0), MATCH('Balance Sheet'!E$3,Overall!$B$3:$F$3,0)),"") -> 5668895193049 | F5: =IFERROR(INDEX(Overall!$B$4:$F$77, MATCH('Balance Sheet'!$C5,Overall!$A$4:$A$77,0), MATCH('Balance Sheet'!F$3,Overall!$B$3:$F$3,0)),"") -> 5567983431468 | G5: =IFERROR(INDEX(Overall!$B$4:$F$77, MATCH('Balance Sheet'!$C5,Overall!$A$4:$A$77,0), MATCH('Balance Sheet'!G$3,Overall!$B$3:$F$3,0)),"") -> 6876468282085
A6: Short Term Investments | B6: Đầu tư tài chính ngắn hạn | C6: 120 | D6: =IFERROR(INDEX(Overall!$B$4:$F$77, MATCH('Balance Sheet'!$C6,Overall!$A$4:$A$77,0), MATCH('Balance Sheet'!D$3,Overall!$B$3:$F$3,0)),"") -> 23726498790237 | E6: =IFERROR(INDEX(Overall!$B$4:$F$77, MATCH('Balance Sheet'!$C6,Overall!$A$4:$A$77,0), MATCH('Balance Sheet'!E$3,Overall!$B$3:$F$3,0)),"") -> 35084645516061 | F6: =IFERROR(INDEX(Overall!$B$4:$F$77, MATCH('Balance Sheet'!$C6,Overall!$A$4:$A$77,0), MATCH('Balance Sheet'!F$3,Overall!$B$3:$F$3,0)),"") -> 27404031282702 | G6: =IFERROR(INDEX(Overall!$B$4:$F$77, MATCH('Balance Sheet'!$C6,Overall!$A$4:$A$77,0), MATCH('Balance Sheet'!G$3,Overall!$B$3:$F$3,0)),"") -> 32890551400598
A7: Net Receivables | B7: Các khoản phải thu thuần | C7: 130 | D7: =IFERROR(INDEX(Overall!$B$4:$F$77, MATCH('Balance Sheet'!$C7,Overall!$A$4:$A$77,0), MATCH('Balance Sheet'!D$3,Overall!$B$3:$F$3,0)),"") -> 16191131770955 | E7: =IFERROR(INDEX(Overall!$B$4:$F$77, MATCH('Balance Sheet'!$C7,Overall!$A$4:$A$77,0), MATCH('Balance Sheet'!E$3,Overall!$B$3:$F$3,0)),"") -> 16865314290394 | F7: =IFERROR(INDEX(Overall!$B$4:$F$77, MATCH('Balance Sheet'!$C7,Overall!$A$4:$A$77,0), MATCH('Balance Sheet'!F$3,Overall!$B$3:$F$3,0)),"") -> 19098417078475 | G7: =IFERROR(INDEX(Overall!$B$4:$F$77, MATCH('Balance Sheet'!$C7,Overall!$A$4:$A$77,0), MATCH('Balance Sheet'!G$3,Overall!$B$3:$F$3,0)),"") -> 24881281586057
A8: Inventory | B8: Hàng tồn kho | C8: 140 | D8: =IFERROR(INDEX(Overall!$B$4:$F$77, MATCH('Balance Sheet'!$C8,Overall!$A$4:$A$77,0), MATCH('Balance Sheet'!D$3,Overall!$B$3:$F$3,0)),"") -> 4102441805643 | E8: =IFERROR(INDEX(Overall!$B$4:$F$77, MATCH('Balance Sheet'!$C8,Overall!$A$4:$A$77,0), MATCH('Balance Sheet'!E$3,Overall!$B$3:$F$3,0)),"") -> 3944544425746 | F8: =IFERROR(INDEX(Overall!$B$4:$F$77, MATCH('Balance Sheet'!$C8,Overall!$A$4:$A$77,0), MATCH('Balance Sheet'!F$3,Overall!$B$3:$F$3,0)),"") -> 4598950949693 | G8: =IFERROR(INDEX(Overall!$B$4:$F$77, MATCH('Balance Sheet'!$C8,Overall!$A$4:$A$77,0), MATCH('Balance Sheet'!G$3,Overall!$B$3:$F$3,0)),"") -> 4398771281185
A9: Other Current Assets | B9: Tài sản ngắn hạn khác | C9: 150 | D9: =IFERROR(INDEX(Overall!$B$4:$F$77, MATCH('Balance Sheet'!$C9,Overall!$A$4:$A$77,0), MATCH('Balance Sheet'!D$3,Overall!$B$3:$F$3,0)),"") -> 1082297952648 | E9: =IFERROR(INDEX(Overall!$B$4:$F$77, MATCH('Balance Sheet'!$C9,Overall!$A$4:$A$77,0), MATCH('Balance Sheet'!E$3,Overall!$B$3:$F$3,0)),"") -> 654352727689 | F9: =IFERROR(INDEX(Overall!$B$4:$F$77, MATCH('Balance Sheet'!$C9,Overall!$A$4:$A$77,0), MATCH('Balance Sheet'!F$3,Overall!$B$3:$F$3,0)),"") -> 531112687800 | G9: =IFERROR(INDEX(Overall!$B$4:$F$77, MATCH('Balance Sheet'!$C9,Overall!$A$4:$A$77,0), MATCH('Balance Sheet'!G$3,Overall!$B$3:$F$3,0)),"") -> 855393085401
A10: Total Current Assets | B10: Tổng tài sản ngắn hạn | C10: 100 | D10: =IFERROR(INDEX(Overall!$B$4:$F$77, MATCH('Balance Sheet'!$C10,Overall!$A$4:$A$77,0), MATCH('Balance Sheet'!D$3,Overall!$B$3:$F$3,0)),"") -> 55651707958020 | E10: =IFERROR(INDEX(Overall!$B$4:$F$77, MATCH('Balance Sheet'!$C10,Overall!$A$4:$A$77,0), MATCH('Balance Sheet'!E$3,Overall!$B$3:$F$3,0)),"") -> 62217752152930 | F10: =IFERROR(INDEX(Overall!$B$4:$F$77, MATCH('Balance Sheet'!$C10,Overall!$A$4:$A$77,0), MATCH('Balance Sheet'!F$3,Overall!$B$3:$F$3,0)),"") -> 57290495430038 | G10: =IFERROR(INDEX(Overall!$B$4:$F$77, MATCH('Balance Sheet'!$C10,Overall!$A$4:$A$77,0), MATCH('Balance Sheet'!G$3,Overall!$B$3:$F$3,0)),"") -> 69902465635326
A11: Long Term Investments | B11: Đầu tư tài chính dài hạn | C11: 250 | D11: =IFERROR(INDEX(Overall!$B$4:$F$77, MATCH('Balance Sheet'!$C11,Overall!$A$4:$A$77,0), MATCH('Balance Sheet'!D$3,Overall!$B$3:$F$3,0)),"") -> 405533457500 | E11: =IFERROR(INDEX(Overall!$B$4:$F$77, MATCH('Balance Sheet'!$C11,Overall!$A$4:$A$77,0), MATCH('Balance Sheet'!E$3,Overall!$B$3:$F$3,0)),"") -> 398010821463 | F11: =IFERROR(INDEX(Overall!$B$4:$F$77, MATCH('Balance Sheet'!$C11,Overall!$A$4:$A$77,0), MATCH('Balance Sheet'!F$3,Overall!$B$3:$F$3,0)),"") -> 399715385824 | G11: =IFERROR(INDEX(Overall!$B$4:$F$77, MATCH('Balance Sheet'!$C11,Overall!$A$4:$A$77,0), MATCH('Balance Sheet'!G$3,Overall!$B$3:$F$3,0)),"") -> 406032256124
A12: Property Plant and Equipment | B12: Tài sản cố định hữu hình (PPE) | C12: 221 | D12: =IFERROR(INDEX(Overall!$B$4:$F$77, MATCH('Balance Sheet'!$C12,Overall!$A$4:$A$77,0), MATCH('Balance Sheet'!D$3,Overall!$B$3:$F$3,0)),"") -> 15975936459471 | E12: =IFERROR(INDEX(Overall!$B$4:$F$77, MATCH('Balance Sheet'!$C12,Overall!$A$4:$A$77,0), MATCH('Balance Sheet'!E$3,Overall!$B$3:$F$3,0)),"") -> 19144905041836 | F12: =IFERROR(INDEX(Overall!$B$4:$F$77, MATCH('Balance Sheet'!$C12,Overall!$A$4:$A$77,0), MATCH('Balance Sheet'!F$3,Overall!$B$3:$F$3,0)),"") -> 17852624248675 | G12: =IFERROR(INDEX(Overall!$B$4:$F$77, MATCH('Balance Sheet'!$C12,Overall!$A$4:$A$77,0), MATCH('Balance Sheet'!G$3,Overall!$B$3:$F$3,0)),"") -> 15574140285441
A13: Goodwill | B13: Lợi thế thương mại | C13: 269 | D13: =IFERROR(INDEX(Overall!$B$4:$F$77, MATCH('Balance Sheet'!$C13,Overall!$A$4:$A$77,0), MATCH('Balance Sheet'!D$3,Overall!$B$3:$F$3,0)),"") | E13: =IFERROR(INDEX(Overall!$B$4:$F$77, MATCH('Balance Sheet'!$C13,Overall!$A$4:$A$77,0), MATCH('Balance Sheet'!E$3,Overall!$B$3:$F$3,0)),"") | F13: =IFERROR(INDEX(Overall!$B$4:$F$77, MATCH('Balance Sheet'!$C13,Overall!$A$4:$A$77,0), MATCH('Balance Sheet'!F$3,Overall!$B$3:$F$3,0)),"") | G13: =IFERROR(INDEX(Overall!$B$4:$F$77, MATCH('Balance Sheet'!$C13,Overall!$A$4:$A$77,0), MATCH('Balance Sheet'!G$3,Overall!$B$3:$F$3,0)),"")
A14: Intangible Assets | B14: Tài sản vô hình | C14: 227 | D14: =IFERROR(INDEX(Overall!$B$4:$F$77, MATCH('Balance Sheet'!$C14,Overall!$A$4:$A$77,0), MATCH('Balance Sheet'!D$3,Overall!$B$3:$F$3,0)),"") -> 393728381555 | E14: =IFERROR(INDEX(Overall!$B$4:$F$77, MATCH('Balance Sheet'!$C14,Overall!$A$4:$A$77,0), MATCH('Balance Sheet'!E$3,Overall!$B$3:$F$3,0)),"") -> 387232909253 | F14: =IFERROR(INDEX(Overall!$B$4:$F$77, MATCH('Balance Sheet'!$C14,Overall!$A$4:$A$77,0), MATCH('Balance Sheet'!F$3,Overall!$B$3:$F$3,0)),"") -> 369012352913 | G14: =IFERROR(INDEX(Overall!$B$4:$F$77, MATCH('Balance Sheet'!$C14,Overall!$A$4:$A$77,0), MATCH('Balance Sheet'!G$3,Overall!$B$3:$F$3,0)),"") -> 376650723714
A15: Accumulated Amortization | B15: Hao mòn lũy kế / Khấu hao lũy kế TSCĐ vô hình | C15: 229 | D15: =IFERROR(INDEX(Overall!$B$4:$F$77, MATCH('Balance Sheet'!$C15,Overall!$A$4:$A$77,0), MATCH('Balance Sheet'!D$3,Overall!$B$3:$F$3,0)),"") -> -226420062447 | E15: =IFERROR(INDEX(Overall!$B$4:$F$77, MATCH('Balance Sheet'!$C15,Overall!$A$4:$A$77,0), MATCH('Balance Sheet'!E$3,Overall!$B$3:$F$3,0)),"") -> -258510465942 | F15: =IFERROR(INDEX(Overall!$B$4:$F$77, MATCH('Balance Sheet'!$C15,Overall!$A$4:$A$77,0), MATCH('Balance Sheet'!F$3,Overall!$B$3:$F$3,0)),"") -> -286560340134 | G15: =IFERROR(INDEX(Overall!$B$4:$F$77, MATCH('Balance Sheet'!$C15,Overall!$A$4:$A$77,0), MATCH('Balance Sheet'!G$3,Overall!$B$3:$F$3,0)),"") -> -304969426663
A16: Other Assets | B16: Tài sản khác | C16: 260 | D16: =IFERROR(INDEX(Overall!$B$4:$F$77, MATCH('Balance Sheet'!$C16,Overall!$A$4:$A$77,0), MATCH('Balance Sheet'!D$3,Overall!$B$3:$F$3,0)),"") -> 4052685959657 | E16: =IFERROR(INDEX(Overall!$B$4:$F$77, MATCH('Balance Sheet'!$C16,Overall!$A$4:$A$77,0), MATCH('Balance Sheet'!E$3,Overall!$B$3:$F$3,0)),"") -> 3475909955425 | F16: =IFERROR(INDEX(Overall!$B$4:$F$77, MATCH('Balance Sheet'!$C16,Overall!$A$4:$A$77,0), MATCH('Balance Sheet'!F$3,Overall!$B$3:$F$3,0)),"") -> 3663465910698 | G16: =IFERROR(INDEX(Overall!$B$4:$F$77, MATCH('Balance Sheet'!$C16,Overall!$A$4:$A$77,0), MATCH('Balance Sheet'!G$3,Overall!$B$3:$F$3,0)),"") -> 3279291799473
... A18: Total Assets | B18: Tổng tài sản | C18: 270 | D18: =IFERROR(INDEX(Overall!$B$4:$F$77, MATCH('Balance Sheet'!$C18,Overall!$A$4:$A$77,0), MATCH('Balance Sheet'!D$3,Overall!$B$3:$F$3,0)),"") -> 82662652366363 | E18: =IFERROR(INDEX(Overall!$B$4:$F$77, MATCH('Balance Sheet'!$C18,Overall!$A$4:$A$77,0), MATCH('Balance Sheet'!E$3,Overall!$B$3:$F$3,0)),"") -> 87754455330448 | F18: =IFERROR(INDEX(Overall!$B$4:$F$77, MATCH('Balance Sheet'!$C18,Overall!$A$4:$A$77,0), MATCH('Balance Sheet'!F$3,Overall!$B$3:$F$3,0)),"") -> 81854881408158 | G18: =IFERROR(INDEX(Overall!$B$4:$F$77, MATCH('Balance Sheet'!$C18,Overall!$A$4:$A$77,0), MATCH('Balance Sheet'!G$3,Overall!$B$3:$F$3,0)),"") -> 93568198109790
A19: Current Liabilities | B19: Nợ phải trả ngắn hạn | D19: =IFERROR(INDEX(Overall!$B$4:$F$77, MATCH('Balance Sheet'!$C19,Overall!$A$4:$A$77,0), MATCH('Balance Sheet'!D$3,Overall!$B$3:$F$3,0)),"") | E19: =IFERROR(INDEX(Overall!$B$4:$F$77, MATCH('Balance Sheet'!$C19,Overall!$A$4:$A$77,0), MATCH('Balance Sheet'!E$3,Overall!$B$3:$F$3,0)),"") | F19: =IFERROR(INDEX(Overall!$B$4:$F$77, MATCH('Balance Sheet'!$C19,Overall!$A$4:$A$77,0), MATCH('Balance Sheet'!F$3,Overall!$B$3:$F$3,0)),"") | G19: =IFERROR(INDEX(Overall!$B$4:$F$77, MATCH('Balance Sheet'!$C19,Overall!$A$4:$A$77,0), MATCH('Balance Sheet'!G$3,Overall!$B$3:$F$3,0)),"")
A20: Accounts Payable | B20: Phải trả người bán | C20: 311 | D20: =IFERROR(INDEX(Overall!$B$4:$F$77, MATCH('Balance Sheet'!$C20,Overall!$A$4:$A$77,0), MATCH('Balance Sheet'!D$3,Overall!$B$3:$F$3,0)),"") -> 6652093471748 | E20: =IFERROR(INDEX(Overall!$B$4:$F$77, MATCH('Balance Sheet'!$C20,Overall!$A$4:$A$77,0), MATCH('Balance Sheet'!E$3,Overall!$B$3:$F$3,0)),"") -> 7137955519190 | F20: =IFERROR(INDEX(Overall!$B$4:$F$77, MATCH('Balance Sheet'!$C20,Overall!$A$4:$A$77,0), MATCH('Balance Sheet'!F$3,Overall!$B$3:$F$3,0)),"") -> 6037010202174 | G20: =IFERROR(INDEX(Overall!$B$4:$F$77, MATCH('Balance Sheet'!$C20,Overall!$A$4:$A$77,0), MATCH('Balance Sheet'!G$3,Overall!$B$3:$F$3,0)),"") -> 11925122947416
A21: Short/Current Long Term Debt | B21: Nợ dài hạn đến hạn trả (ngắn hạn) | C21: 315 | D21: =IFERROR(INDEX(Overall!$B$4:$F$77, MATCH('Balance Sheet'!$C21,Overall!$A$4:$A$77,0), MATCH('Balance Sheet'!D$3,Overall!$B$3:$F$3,0)),"") -> 2978023503077 | E21: =IFERROR(INDEX(Overall!$B$4:$F$77, MATCH('Balance Sheet'!$C21,Overall!$A$4:$A$77,0), MATCH('Balance Sheet'!E$3,Overall!$B$3:$F$3,0)),"") -> 2844331963463 | F21: =IFERROR(INDEX(Overall!$B$4:$F$77, MATCH('Balance Sheet'!$C21,Overall!$A$4:$A$77,0), MATCH('Balance Sheet'!F$3,Overall!$B$3:$F$3,0)),"") -> 2995123654976 | G21: =IFERROR(INDEX(Overall!$B$4:$F$77, MATCH('Balance Sheet'!$C21,Overall!$A$4:$A$77,0), MATCH('Balance Sheet'!G$3,Overall!$B$3:$F$3,0)),"") -> 4226253151500
A22: Other Current Liabilities | B22: Nợ ngắn hạn khác | C22: 319 | D22: =IFERROR(INDEX(Overall!$B$4:$F$77, MATCH('Balance Sheet'!$C22,Overall!$A$4:$A$77,0), MATCH('Balance Sheet'!D$3,Overall!$B$3:$F$3,0)),"") -> 836431004097 | E22: =IFERROR(INDEX(Overall!$B$4:$F$77, MATCH('Balance Sheet'!$C22,Overall!$A$4:$A$77,0), MATCH('Balance Sheet'!E$3,Overall!$B$3:$F$3,0)),"") -> 624739245695 | F22: =IFERROR(INDEX(Overall!$B$4:$F$77, MATCH('Balance Sheet'!$C22,Overall!$A$4:$A$77,0), MATCH('Balance Sheet'!F$3,Overall!$B$3:$F$3,0)),"") -> 373838581752 | G22: =IFERROR(INDEX(Overall!$B$4:$F$77, MATCH('Balance Sheet'!$C22,Overall!$A$4:$A$77,0), MATCH('Balance Sheet'!G$3,Overall!$B$3:$F$3,0)),"") -> 333114428193
A23: Total Current Liabilities | B23: Tổng nợ phải trả ngắn hạn | C23: 310 | D23: =IFERROR(INDEX(Overall!$B$4:$F$77, MATCH('Balance Sheet'!$C23,Overall!$A$4:$A$77,0), MATCH('Balance Sheet'!D$3,Overall!$B$3:$F$3,0)),"") -> 12487956920689 | E23: =IFERROR(INDEX(Overall!$B$4:$F$77, MATCH('Balance Sheet'!$C23,Overall!$A$4:$A$77,0), MATCH('Balance Sheet'!E$3,Overall!$B$3:$F$3,0)),"") -> 14971948871764 | F23: =IFERROR(INDEX(Overall!$B$4:$F$77, MATCH('Balance Sheet'!$C23,Overall!$A$4:$A$77,0), MATCH('Balance Sheet'!F$3,Overall!$B$3:$F$3,0)),"") -> 14575489059608 | G23: =IFERROR(INDEX(Overall!$B$4:$F$77, MATCH('Balance Sheet'!$C23,Overall!$A$4:$A$77,0), MATCH('Balance Sheet'!G$3,Overall!$B$3:$F$3,0)),"") -> 20573719389418
A24: Long Term Debt | B24: Nợ dài hạn | C24: 330 | D24: =IFERROR(INDEX(Overall!$B$4:$F$77, MATCH('Balance Sheet'!$C24,Overall!$A$4:$A$77,0), MATCH('Balance Sheet'!D$3,Overall!$B$3:$F$3,0)),"") -> 9001131890533 | E24: =IFERROR(INDEX(Overall!$B$4:$F$77, MATCH('Balance Sheet'!$C24,Overall!$A$4:$A$77,0), MATCH('Balance Sheet'!E$3,Overall!$B$3:$F$3,0)),"") -> 7483886184291 | F24: =IFERROR(INDEX(Overall!$B$4:$F$77, MATCH('Balance Sheet'!$C24,Overall!$A$4:$A$77,0), MATCH('Balance Sheet'!F$3,Overall!$B$3:$F$3,0)),"") -> 5708397082920 | G24: =IFERROR(INDEX(Overall!$B$4:$F$77, MATCH('Balance Sheet'!$C24,Overall!$A$4:$A$77,0), MATCH('Balance Sheet'!G$3,Overall!$B$3:$F$3,0)),"") -> 5341089602435
A25: Other Liabilities | B25: Nợ phải trả khác | C25: 337 | D25: =IFERROR(INDEX(Overall!$B$4:$F$77, MATCH('Balance Sheet'!$C25,Overall!$A$4:$A$77,0), MATCH('Balance Sheet'!D$3,Overall!$B$3:$F$3,0)),"") -> 140713909427 | E25: =IFERROR(INDEX(Overall!$B$4:$F$77, MATCH('Balance Sheet'!$C25,Overall!$A$4:$A$77,0), MATCH('Balance Sheet'!E$3,Overall!$B$3:$F$3,0)),"") -> 156066914797 | F25: =IFERROR(INDEX(Overall!$B$4:$F$77, MATCH('Balance Sheet'!$C25,Overall!$A$4:$A$77,0), MATCH('Balance Sheet'!F$3,Overall!$B$3:$F$3,0)),"") -> 129700198659 | G25: =IFERROR(INDEX(Overall!$B$4:$F$77, MATCH('Balance Sheet'!$C25,Overall!$A$4:$A$77,0), MATCH('Balance Sheet'!G$3,Overall!$B$3:$F$3,0)),"") -> 109883490101
A26: Deferred Long Term Liability Charges | B26: Thuế và chi phí phải trả hoãn lại dài hạn | C26: 341 | D26: =IFERROR(INDEX(Overall!$B$4:$F$77, MATCH('Balance Sheet'!$C26,Overall!$A$4:$A$77,0), MATCH('Balance Sheet'!D$3,Overall!$B$3:$F$3,0)),"") -> 253194790414 | E26: =IFERROR(INDEX(Overall!$B$4:$F$77, MATCH('Balance Sheet'!$C26,Overall!$A$4:$A$77,0), MATCH('Balance Sheet'!E$3,Overall!$B$3:$F$3,0)),"") -> 279708433761 | F26: =IFERROR(INDEX(Overall!$B$4:$F$77, MATCH('Balance Sheet'!$C26,Overall!$A$4:$A$77,0), MATCH('Balance Sheet'!F$3,Overall!$B$3:$F$3,0)),"") -> 293780671709 | G26: =IFERROR(INDEX(Overall!$B$4:$F$77, MATCH('Balance Sheet'!$C26,Overall!$A$4:$A$77,0), MATCH('Balance Sheet'!G$3,Overall!$B$3:$F$3,0)),"") -> 283528428389
A27: Minority Interest | B27: Lợi ích cổ đông không kiểm soát | C27: 429 | D27: =IFERROR(INDEX(Overall!$B$4:$F$77, MATCH('Balance Sheet'!$C27,Overall!$A$4:$A$77,0), MATCH('Balance Sheet'!D$3,Overall!$B$3:$F$3,0)),"") -> 1315888895212 | E27: =IFERROR(INDEX(Overall!$B$4:$F$77, MATCH('Balance Sheet'!$C27,Overall!$A$4:$A$77,0), MATCH('Balance Sheet'!E$3,Overall!$B$3:$F$3,0)),"") -> 1249889464218 | F27: =IFERROR(INDEX(Overall!$B$4:$F$77, MATCH('Balance Sheet'!$C27,Overall!$A$4:$A$77,0), MATCH('Balance Sheet'!F$3,Overall!$B$3:$F$3,0)),"") -> 1323213381181 | G27: =IFERROR(INDEX(Overall!$B$4:$F$77, MATCH('Balance Sheet'!$C27,Overall!$A$4:$A$77,0), MATCH('Balance Sheet'!G$3,Overall!$B$3:$F$3,0)),"") -> 1358410438814
A28: Negative Goodwill | B28: Lợi thế thương mại âm | D28: =IFERROR(INDEX(Overall!$B$4:$F$77, MATCH('Balance Sheet'!$C28,Overall!$A$4:$A$77,0), MATCH('Balance Sheet'!D$3,Overall!$B$3:$F$3,0)),"") | E28: =IFERROR(INDEX(Overall!$B$4:$F$77, MATCH('Balance Sheet'!$C28,Overall!$A$4:$A$77,0), MATCH('Balance Sheet'!E$3,Overall!$B$3:$F$3,0)),"") | F28: =IFERROR(INDEX(Overall!$B$4:$F$77, MATCH('Balance Sheet'!$C28,Overall!$A$4:$A$77,0), MATCH('Balance Sheet'!F$3,Overall!$B$3:$F$3,0)),"") | G28: =IFERROR(INDEX(Overall!$B$4:$F$77, MATCH('Balance Sheet'!$C28,Overall!$A$4:$A$77,0), MATCH('Balance Sheet'!G$3,Overall!$B$3:$F$3,0)),"")
A29: Total Liabilities | B29: Tổng nợ phải trả | C29: 400 | D29: =IFERROR(INDEX(Overall!$B$4:$F$77, MATCH('Balance Sheet'!$C29,Overall!$A$4:$A$77,0), MATCH('Balance Sheet'!D$3,Overall!$B$3:$F$3,0)),"") -> 61173563555141 | E29: =IFERROR(INDEX(Overall!$B$4:$F$77, MATCH('Balance Sheet'!$C29,Overall!$A$4:$A$77,0), MATCH('Balance Sheet'!E$3,Overall!$B$3:$F$3,0)),"") -> 65298620274393 | F29: =IFERROR(INDEX(Overall!$B$4:$F$77, MATCH('Balance Sheet'!$C29,Overall!$A$4:$A$77,0), MATCH('Balance Sheet'!F$3,Overall!$B$3:$F$3,0)),"") -> 61570995265630 | G29: =IFERROR(INDEX(Overall!$B$4:$F$77, MATCH('Balance Sheet'!$C29,Overall!$A$4:$A$77,0), MATCH('Balance Sheet'!G$3,Overall!$B$3:$F$3,0)),"") -> 67653389117937
A30: Stockholders' Equity | B30: Vốn chủ sở hữu | D30: =IFERROR(INDEX(Overall!$B$4:$F$77, MATCH('Balance Sheet'!$C30,Overall!$A$4:$A$77,0), MATCH('Balance Sheet'!D$3,Overall!$B$3:$F$3,0)),"") | E30: =IFERROR(INDEX(Overall!$B$4:$F$77, MATCH('Balance Sheet'!$C30,Overall!$A$4:$A$77,0), MATCH('Balance Sheet'!E$3,Overall!$B$3:$F$3,0)),"") | F30: =IFERROR(INDEX(Overall!$B$4:$F$77, MATCH('Balance Sheet'!$C30,Overall!$A$4:$A$77,0), MATCH('Balance Sheet'!F$3,Overall!$B$3:$F$3,0)),"") | G30: =IFERROR(INDEX(Overall!$B$4:$F$77, MATCH('Balance Sheet'!$C30,Overall!$A$4:$A$77,0), MATCH('Balance Sheet'!G$3,Overall!$B$3:$F$3,0)),"")
A31: Misc. Stocks Options Warrants | B31: Quyền chọn cổ phiếu và chứng quyền | D31: =IFERROR(INDEX(Overall!$B$4:$F$77, MATCH('Balance Sheet'!$C31,Overall!$A$4:$A$77,0), MATCH('Balance Sheet'!D$3,Overall!$B$3:$F$3,0)),"") | E31: =IFERROR(INDEX(Overall!$B$4:$F$77, MATCH('Balance Sheet'!$C31,Overall!$A$4:$A$77,0), MATCH('Balance Sheet'!E$3,Overall!$B$3:$F$3,0)),"") | F31: =IFERROR(INDEX(Overall!$B$4:$F$77, MATCH('Balance Sheet'!$C31,Overall!$A$4:$A$77,0), MATCH('Balance Sheet'!F$3,Overall!$B$3:$F$3,0)),"") | G31: =IFERROR(INDEX(Overall!$B$4:$F$77, MATCH('Balance Sheet'!$C31,Overall!$A$4:$A$77,0), MATCH('Balance Sheet'!G$3,Overall!$B$3:$F$3,0)),"")
A32: Redeemable Preferred Stock | B32: Cổ phiếu ưu đãi có thể mua lại | C32: 411 | D32: =IFERROR(INDEX(Overall!$B$4:$F$77, MATCH('Balance Sheet'!$C32,Overall!$A$4:$A$77,0), MATCH('Balance Sheet'!D$3,Overall!$B$3:$F$3,0)),"") -> 19139500000000 | E32: =IFERROR(INDEX(Overall!$B$4:$F$77, MATCH('Balance Sheet'!$C32,Overall!$A$4:$A$77,0), MATCH('Balance Sheet'!E$3,Overall!$B$3:$F$3,0)),"") -> 22967398470000 | F32: =IFERROR(INDEX(Overall!$B$4:$F$77, MATCH('Balance Sheet'!$C32,Overall!$A$4:$A$77,0), MATCH('Balance Sheet'!F$3,Overall!$B$3:$F$3,0)),"") -> 23426729190000 | G32: =IFERROR(INDEX(Overall!$B$4:$F$77, MATCH('Balance Sheet'!$C32,Overall!$A$4:$A$77,0), MATCH('Balance Sheet'!G$3,Overall!$B$3:$F$3,0)),"") -> 24129497560000
A33: Preferred Stock | B33: Cổ phiếu ưu đãi | D33: =IFERROR(INDEX(Overall!$B$4:$F$77, MATCH('Balance Sheet'!$C33,Overall!$A$4:$A$77,0), MATCH('Balance Sheet'!D$3,Overall!$B$3:$F$3,0)),"") | E33: =IFERROR(INDEX(Overall!$B$4:$F$77, MATCH('Balance Sheet'!$C33,Overall!$A$4:$A$77,0), MATCH('Balance Sheet'!E$3,Overall!$B$3:$F$3,0)),"") | F33: =IFERROR(INDEX(Overall!$B$4:$F$77, MATCH('Balance Sheet'!$C33,Overall!$A$4:$A$77,0), MATCH('Balance Sheet'!F$3,Overall!$B$3:$F$3,0)),"") | G33: =IFERROR(INDEX(Overall!$B$4:$F$77, MATCH('Balance Sheet'!$C33,Overall!$A$4:$A$77,0), MATCH('Balance Sheet'!G$3,Overall!$B$3:$F$3,0)),"")
A34: Common Stock | B34: Cổ phiếu phổ thông | C34: 411a | D34: =IFERROR(INDEX(Overall!$B$4:$F$77, MATCH('Balance Sheet'!$C34,Overall!$A$4:$A$77,0), MATCH('Balance Sheet'!D$3,Overall!$B$3:$F$3,0)),"") -> 19139500000000 | E34: =IFERROR(INDEX(Overall!$B$4:$F$77, MATCH('Balance Sheet'!$C34,Overall!$A$4:$A$77,0), MATCH('Balance Sheet'!E$3,Overall!$B$3:$F$3,0)),"") -> 22967398470000 | F34: =IFERROR(INDEX(Overall!$B$4:$F$77, MATCH('Balance Sheet'!$C34,Overall!$A$4:$A$77,0), MATCH('Balance Sheet'!F$3,Overall!$B$3:$F$3,0)),"") -> 23426729190000 | G34: =IFERROR(INDEX(Overall!$B$4:$F$77, MATCH('Balance Sheet'!$C34,Overall!$A$4:$A$77,0), MATCH('Balance Sheet'!G$3,Overall!$B$3:$F$3,0)),"") -> 24129497560000
A35: Retained Earnings | B35: Lợi nhuận sau thuế chưa phân phối | C35: 421 | D35: =IFERROR(INDEX(Overall!$B$4:$F$77, MATCH('Balance Sheet'!$C35,Overall!$A$4:$A$77,0), MATCH('Balance Sheet'!D$3,Overall!$B$3:$F$3,0)),"") -> 19241492510616 | E35: =IFERROR(INDEX(Overall!$B$4:$F$77, MATCH('Balance Sheet'!$C35,Overall!$A$4:$A$77,0), MATCH('Balance Sheet'!E$3,Overall!$B$3:$F$3,0)),"") -> 16879761088028 | F35: =IFERROR(INDEX(Overall!$B$4:$F$77, MATCH('Balance Sheet'!$C35,Overall!$A$4:$A$77,0), MATCH('Balance Sheet'!F$3,Overall!$B$3:$F$3,0)),"") -> 9553019715422 | G35: =IFERROR(INDEX(Overall!$B$4:$F$77, MATCH('Balance Sheet'!$C35,Overall!$A$4:$A$77,0), MATCH('Balance Sheet'!G$3,Overall!$B$3:$F$3,0)),"") -> 12484110062726
A36: Treasury Stock | B36: Cổ phiếu quỹ | D36: =IFERROR(INDEX(Overall!$B$4:$F$77, MATCH('Balance Sheet'!$C36,Overall!$A$4:$A$77,0), MATCH('Balance Sheet'!D$3,Overall!$B$3:$F$3,0)),"") | E36: =IFERROR(INDEX(Overall!$B$4:$F$77, MATCH('Balance Sheet'!$C36,Overall!$A$4:$A$77,0), MATCH('Balance Sheet'!E$3,Overall!$B$3:$F$3,0)),"") | F36: =IFERROR(INDEX(Overall!$B$4:$F$77, MATCH('Balance Sheet'!$C36,Overall!$A$4:$A$77,0), MATCH('Balance Sheet'!F$3,Overall!$B$3:$F$3,0)),"") | G36: =IFERROR(INDEX(Overall!$B$4:$F$77, MATCH('Balance Sheet'!$C36,Overall!$A$4:$A$77,0), MATCH('Balance Sheet'!G$3,Overall!$B$3:$F$3,0)),"")
A37: Capital Surplus | B37: Thặng dư vốn cổ phần | C37: 412 | D37: =IFERROR(INDEX(Overall!$B$4:$F$77, MATCH('Balance Sheet'!$C37,Overall!$A$4:$A$77,0), MATCH('Balance Sheet'!D$3,Overall!$B$3:$F$3,0)),"") -> 210679541297 | E37: =IFERROR(INDEX(Overall!$B$4:$F$77, MATCH('Balance Sheet'!$C37,Overall!$A$4:$A$77,0), MATCH('Balance Sheet'!E$3,Overall!$B$3:$F$3,0)),"") -> 246727266 | F37: =IFERROR(INDEX(Overall!$B$4:$F$77, MATCH('Balance Sheet'!$C37,Overall!$A$4:$A$77,0), MATCH('Balance Sheet'!F$3,Overall!$B$3:$F$3,0)),"") -> 246727266 | G37: =IFERROR(INDEX(Overall!$B$4:$F$77, MATCH('Balance Sheet'!$C37,Overall!$A$4:$A$77,0), MATCH('Balance Sheet'!G$3,Overall!$B$3:$F$3,0)),"") -> 246727266
A38: Other Stockholder Equity | B38: Vốn chủ sở hữu khác | C38: 414 | D38: =IFERROR(INDEX(Overall!$B$4:$F$77, MATCH('Balance Sheet'!$C38,Overall!$A$4:$A$77,0), MATCH('Balance Sheet'!D$3,Overall!$B$3:$F$3,0)),"") -> 196658562648 | E38: =IFERROR(INDEX(Overall!$B$4:$F$77, MATCH('Balance Sheet'!$C38,Overall!$A$4:$A$77,0), MATCH('Balance Sheet'!E$3,Overall!$B$3:$F$3,0)),"") -> 282322856474 | F38: =IFERROR(INDEX(Overall!$B$4:$F$77, MATCH('Balance Sheet'!$C38,Overall!$A$4:$A$77,0), MATCH('Balance Sheet'!F$3,Overall!$B$3:$F$3,0)),"") -> 300272460670 | G38: =IFERROR(INDEX(Overall!$B$4:$F$77, MATCH('Balance Sheet'!$C38,Overall!$A$4:$A$77,0), MATCH('Balance Sheet'!G$3,Overall!$B$3:$F$3,0)),"") -> 300272460670
A39: Total Stockholder Equity | B39: Tổng vốn chủ sở hữu | C39: 410 | D39: =IFERROR(INDEX(Overall!$B$4:$F$77, MATCH('Balance Sheet'!$C39,Overall!$A$4:$A$77,0), MATCH('Balance Sheet'!D$3,Overall!$B$3:$F$3,0)),"") -> 61173563555141 | E39: =IFERROR(INDEX(Overall!$B$4:$F$77, MATCH('Balance Sheet'!$C39,Overall!$A$4:$A$77,0), MATCH('Balance Sheet'!E$3,Overall!$B$3:$F$3,0)),"") -> 65298620274393 | F39: =IFERROR(INDEX(Overall!$B$4:$F$77, MATCH('Balance Sheet'!$C39,Overall!$A$4:$A$77,0), MATCH('Balance Sheet'!F$3,Overall!$B$3:$F$3,0)),"") -> 61570995265630 | G39: =IFERROR(INDEX(Overall!$B$4:$F$77, MATCH('Balance Sheet'!$C39,Overall!$A$4:$A$77,0), MATCH('Balance Sheet'!G$3,Overall!$B$3:$F$3,0)),"") -> 67653389117937
A40: Net Tangible Assets | B40: Tài sản hữu hình thuần | D40: =IFERROR(INDEX(Overall!$B$4:$F$77, MATCH('Balance Sheet'!$C40,Overall!$A$4:$A$77,0), MATCH('Balance Sheet'!D$3,Overall!$B$3:$F$3,0)),"") | E40: =IFERROR(INDEX(Overall!$B$4:$F$77, MATCH('Balance Sheet'!$C40,Overall!$A$4:$A$77,0), MATCH('Balance Sheet'!E$3,Overall!$B$3:$F$3,0)),"") | F40: =IFERROR(INDEX(Overall!$B$4:$F$77, MATCH('Balance Sheet'!$C40,Overall!$A$4:$A$77,0), MATCH('Balance Sheet'!F$3,Overall!$B$3:$F$3,0)),"") | G40: =IFERROR(INDEX(Overall!$B$4:$F$77, MATCH('Balance Sheet'!$C40,Overall!$A$4:$A$77,0), MATCH('Balance Sheet'!G$3,Overall!$B$3:$F$3,0)),"")

Sheet Income Statement
A1: Income Statement
A2: All numbers in dong | B2: Tất cả số liệu tính theo đồng
C3: Mã số | D3: 2022 | E3: 2023 | F3: 2024 | G3: 2025
A4: Revenue | B4: Doanh thu
A5: Total Revenue | B5: Tổng doanh thu | C5: 1 | D5: =IFERROR(INDEX(Overall!$A$81:$F$103, MATCH('Income Statement'!$C5,Overall!$A$81:$A$103,0), MATCH('Income Statement'!D$3,Overall!$A$80:$F$80,0)),"") -> 100723549227433 | E5: =IFERROR(INDEX(Overall!$A$81:$F$103, MATCH('Income Statement'!$C5,Overall!$A$81:$A$103,0), MATCH('Income Statement'!E$3,Overall!$A$80:$F$80,0)),"") -> 90014136902542 | F5: =IFERROR(INDEX(Overall!$A$81:$F$103, MATCH('Income Statement'!$C5,Overall!$A$81:$A$103,0), MATCH('Income Statement'!F$3,Overall!$A$80:$F$80,0)),"") -> 103603614927247 | G5: =IFERROR(INDEX(Overall!$A$81:$F$103, MATCH('Income Statement'!$C5,Overall!$A$81:$A$103,0), MATCH('Income Statement'!G$3,Overall!$A$80:$F$80,0)),"") -> 135196548909363
A6: Cost of Revenue | B6: Giá vốn hàng bán | C6: 11 | D6: =IFERROR(INDEX(Overall!$A$81:$F$103, MATCH('Income Statement'!$C6,Overall!$A$81:$A$103,0), MATCH('Income Statement'!D$3,Overall!$A$80:$F$80,0)),"") -> 79409012569544 | E6: =IFERROR(INDEX(Overall!$A$81:$F$103, MATCH('Income Statement'!$C6,Overall!$A$81:$A$103,0), MATCH('Income Statement'!E$3,Overall!$A$80:$F$80,0)),"") -> 73028985057627 | F6: =IFERROR(INDEX(Overall!$A$81:$F$103, MATCH('Income Statement'!$C6,Overall!$A$81:$A$103,0), MATCH('Income Statement'!F$3,Overall!$A$80:$F$80,0)),"") -> 85909769124140 | G6: =IFERROR(INDEX(Overall!$A$81:$F$103, MATCH('Income Statement'!$C6,Overall!$A$81:$A$103,0), MATCH('Income Statement'!G$3,Overall!$A$80:$F$80,0)),"") -> 118078501968730
A7: Gross Profit | B7: Lợi nhuận gộp | C7: 20 | D7: =IFERROR(INDEX(Overall!$A$81:$F$103, MATCH('Income Statement'!$C7,Overall!$A$81:$A$103,0), MATCH('Income Statement'!D$3,Overall!$A$80:$F$80,0)),"") -> 21314536657889 | E7: =IFERROR(INDEX(Overall!$A$81:$F$103, MATCH('Income Statement'!$C7,Overall!$A$81:$A$103,0), MATCH('Income Statement'!E$3,Overall!$A$80:$F$80,0)),"") -> 16924921455698 | F7: =IFERROR(INDEX(Overall!$A$81:$F$103, MATCH('Income Statement'!$C7,Overall!$A$81:$A$103,0), MATCH('Income Statement'!F$3,Overall!$A$80:$F$80,0)),"") -> 17654357438748 | G7: =IFERROR(INDEX(Overall!$A$81:$F$103, MATCH('Income Statement'!$C7,Overall!$A$81:$A$103,0), MATCH('Income Statement'!G$3,Overall!$A$80:$F$80,0)),"") -> 17050553359665
A8: Operating Expenses | B8: Chi phí hoạt động | D8: =IFERROR(INDEX(Overall!$A$81:$F$103, MATCH('Income Statement'!$C8,Overall!$A$81:$A$103,0), MATCH('Income Statement'!D$3,Overall!$A$80:$F$80,0)),"") | E8: =IFERROR(INDEX(Overall!$A$81:$F$103, MATCH('Income Statement'!$C8,Overall!$A$81:$A$103,0), MATCH('Income Statement'!E$3,Overall!$A$80:$F$80,0)),"") | F8: =IFERROR(INDEX(Overall!$A$81:$F$103, MATCH('Income Statement'!$C8,Overall!$A$81:$A$103,0), MATCH('Income Statement'!F$3,Overall!$A$80:$F$80,0)),"") | G8: =IFERROR(INDEX(Overall!$A$81:$F$103, MATCH('Income Statement'!$C8,Overall!$A$81:$A$103,0), MATCH('Income Statement'!G$3,Overall!$A$80:$F$80,0)),"")
A9: Research Development | B9: Chi phí nghiên cứu và phát triển (R&D) | C9: 0 | D9: =IFERROR(INDEX(Overall!$A$81:$F$103, MATCH('Income Statement'!$C9,Overall!$A$81:$A$103,0), MATCH('Income Statement'!D$3,Overall!$A$80:$F$80,0)),"") | E9: =IFERROR(INDEX(Overall!$A$81:$F$103, MATCH('Income Statement'!$C9,Overall!$A$81:$A$103,0), MATCH('Income Statement'!E$3,Overall!$A$80:$F$80,0)),"") | F9: =IFERROR(INDEX(Overall!$A$81:$F$103, MATCH('Income Statement'!$C9,Overall!$A$81:$A$103,0), MATCH('Income Statement'!F$3,Overall!$A$80:$F$80,0)),"") | G9: =IFERROR(INDEX(Overall!$A$81:$F$103, MATCH('Income Statement'!$C9,Overall!$A$81:$A$103,0), MATCH('Income Statement'!G$3,Overall!$A$80:$F$80,0)),"")
A10: Selling General and Administrative | B10: Chi phí bán hàng và quản lý doanh nghiệp (SG&A) | C10: 25+26 | D10: =Overall!C90+Overall!C91 -> 3515143127222 | E10: =Overall!D90+Overall!D91 -> 4018728746686 | F10: =Overall!E90+Overall!E91 -> 5612323377073 | G10: =Overall!F90+Overall!F91 -> 3926038296884
A11: Non Recurring | B11: Chi phí không thường xuyên | C11: 0 | D11: =IFERROR(INDEX(Overall!$A$81:$F$103, MATCH('Income Statement'!$C11,Overall!$A$81:$A$103,0), MATCH('Income Statement'!D$3,Overall!$A$80:$F$80,0)),"") | E11: =IFERROR(INDEX(Overall!$A$81:$F$103, MATCH('Income Statement'!$C11,Overall!$A$81:$A$103,0), MATCH('Income Statement'!E$3,Overall!$A$80:$F$80,0)),"") | F11: =IFERROR(INDEX(Overall!$A$81:$F$103, MATCH('Income Statement'!$C11,Overall!$A$81:$A$103,0), MATCH('Income Statement'!F$3,Overall!$A$80:$F$80,0)),"") | G11: =IFERROR(INDEX(Overall!$A$81:$F$103, MATCH('Income Statement'!$C11,Overall!$A$81:$A$103,0), MATCH('Income Statement'!G$3,Overall!$A$80:$F$80,0)),"")
A12: Others | B12: Chi phí khác | C12: 32 | D12: =IFERROR(INDEX(Overall!$A$81:$F$103, MATCH('Income Statement'!$C12,Overall!$A$81:$A$103,0), MATCH('Income Statement'!D$3,Overall!$A$80:$F$80,0)),"") -> 33582435496 | E12: =IFERROR(INDEX(Overall!$A$81:$F$103, MATCH('Income Statement'!$C12,Overall!$A$81:$A$103,0), MATCH('Income Statement'!E$3,Overall!$A$80:$F$80,0)),"") -> 13131027226 | F12: =IFERROR(INDEX(Overall!$A$81:$F$103, MATCH('Income Statement'!$C12,Overall!$A$81:$A$103,0), MATCH('Income Statement'!F$3,Overall!$A$80:$F$80,0)),"") -> 25904427886 | G12: =IFERROR(INDEX(Overall!$A$81:$F$103, MATCH('Income Statement'!$C12,Overall!$A$81:$A$103,0), MATCH('Income Statement'!G$3,Overall!$A$80:$F$80,0)),"") -> 69530497916
A13: Total Operating Expenses | B13: Tổng chi phí hoạt động | C13: 25 + 26 + 22 | D13: =Overall!C90+Overall!C91+Overall!C87 -> 4186538604301 | E13: =Overall!D90+Overall!D91+Overall!D87 -> 4605441824575 | F13: =Overall!E90+Overall!E91+Overall!E87 -> 6272371122472 | G13: =Overall!F90+Overall!F91+Overall!F87 -> 4309617584854
A14: Operating Income or Loss | B14: Lợi nhuận (lỗ) từ hoạt động kinh doanh | C14: 30 | D14: =IFERROR(INDEX(Overall!$A$81:$F$103, MATCH('Income Statement'!$C14,Overall!$A$81:$A$103,0), MATCH('Income Statement'!D$3,Overall!$A$80:$F$80,0)),"") -> 18727890017478 | E14: =IFERROR(INDEX(Overall!$A$81:$F$103, MATCH('Income Statement'!$C14,Overall!$A$81:$A$103,0), MATCH('Income Statement'!E$3,Overall!$A$80:$F$80,0)),"") -> 14619122980234 | F14: =IFERROR(INDEX(Overall!$A$81:$F$103, MATCH('Income Statement'!$C14,Overall!$A$81:$A$103,0), MATCH('Income Statement'!F$3,Overall!$A$80:$F$80,0)),"") -> 13156405325870 | G14: =IFERROR(INDEX(Overall!$A$81:$F$103, MATCH('Income Statement'!$C14,Overall!$A$81:$A$103,0), MATCH('Income Statement'!G$3,Overall!$A$80:$F$80,0)),"") -> 14362992025148
A15: Income from Continuing Operations | B15: Lợi nhuận từ hoạt động kinh doanh liên tục | D15: =IFERROR(INDEX(Overall!$A$81:$F$103, MATCH('Income Statement'!$C15,Overall!$A$81:$A$103,0), MATCH('Income Statement'!D$3,Overall!$A$80:$F$80,0)),"") | E15: =IFERROR(INDEX(Overall!$A$81:$F$103, MATCH('Income Statement'!$C15,Overall!$A$81:$A$103,0), MATCH('Income Statement'!E$3,Overall!$A$80:$F$80,0)),"") | F15: =IFERROR(INDEX(Overall!$A$81:$F$103, MATCH('Income Statement'!$C15,Overall!$A$81:$A$103,0), MATCH('Income Statement'!F$3,Overall!$A$80:$F$80,0)),"") | G15: =IFERROR(INDEX(Overall!$A$81:$F$103, MATCH('Income Statement'!$C15,Overall!$A$81:$A$103,0), MATCH('Income Statement'!G$3,Overall!$A$80:$F$80,0)),"")
A16: Total Other Income/Expenses Net | B16: Tổng thu nhập/(chi phí) khác (thuần) | C16: 40 | D16: =IFERROR(INDEX(Overall!$A$81:$F$103, MATCH('Income Statement'!$C16,Overall!$A$81:$A$103,0), MATCH('Income Statement'!D$3,Overall!$A$80:$F$80,0)),"") -> 78384842910 | E16: =IFERROR(INDEX(Overall!$A$81:$F$103, MATCH('Income Statement'!$C16,Overall!$A$81:$A$103,0), MATCH('Income Statement'!E$3,Overall!$A$80:$F$80,0)),"") -> 20419228976 | F16: =IFERROR(INDEX(Overall!$A$81:$F$103, MATCH('Income Statement'!$C16,Overall!$A$81:$A$103,0), MATCH('Income Statement'!F$3,Overall!$A$80:$F$80,0)),"") -> 15702170505 | G16: =IFERROR(INDEX(Overall!$A$81:$F$103, MATCH('Income Statement'!$C16,Overall!$A$81:$A$103,0), MATCH('Income Statement'!G$3,Overall!$A$80:$F$80,0)),"") -> -3556841289
A17: Earnings Before Interest and Taxes | B17: Lợi nhuận trước lãi vay và thuế (EBIT) | C17: 30 + 23 | D17: =Overall!C92+Overall!C88 -> 19064751040575 | E17: =Overall!D92+Overall!D88 -> 14959099036792 | F17: =Overall!E92+Overall!E88 -> 13475002279245 | G17: =Overall!F92+Overall!F88 -> 14579048349855
A18: Interest Expense | B18: Chi phí lãi vay | C18: 23 | D18: =IFERROR(INDEX(Overall!$A$81:$F$103, MATCH('Income Statement'!$C18,Overall!$A$81:$A$103,0), MATCH('Income Statement'!D$3,Overall!$A$80:$F$80,0)),"") -> 336861023097 | E18: =IFERROR(INDEX(Overall!$A$81:$F$103, MATCH('Income Statement'!$C18,Overall!$A$81:$A$103,0), MATCH('Income Statement'!E$3,Overall!$A$80:$F$80,0)),"") -> 339976056558 | F18: =IFERROR(INDEX(Overall!$A$81:$F$103, MATCH('Income Statement'!$C18,Overall!$A$81:$A$103,0), MATCH('Income Statement'!F$3,Overall!$A$80:$F$80,0)),"") -> 318596953375 | G18: =IFERROR(INDEX(Overall!$A$81:$F$103, MATCH('Income Statement'!$C18,Overall!$A$81:$A$103,0), MATCH('Income Statement'!G$3,Overall!$A$80:$F$80,0)),"") -> 216056324707
A19: Income Before Tax | B19: Lợi nhuận trước thuế | C19: 50 | D19: =IFERROR(INDEX(Overall!$A$81:$F$103, MATCH('Income Statement'!$C19,Overall!$A$81:$A$103,0), MATCH('Income Statement'!D$3,Overall!$A$80:$F$80,0)),"") -> 18806274860388 | E19: =IFERROR(INDEX(Overall!$A$81:$F$103, MATCH('Income Statement'!$C19,Overall!$A$81:$A$103,0), MATCH('Income Statement'!E$3,Overall!$A$80:$F$80,0)),"") -> 14639542209210 | F19: =IFERROR(INDEX(Overall!$A$81:$F$103, MATCH('Income Statement'!$C19,Overall!$A$81:$A$103,0), MATCH('Income Statement'!F$3,Overall!$A$80:$F$80,0)),"") -> 13172107496375 | G19: =IFERROR(INDEX(Overall!$A$81:$F$103, MATCH('Income Statement'!$C19,Overall!$A$81:$A$103,0), MATCH('Income Statement'!G$3,Overall!$A$80:$F$80,0)),"") -> 14359435183859
A20: Income Tax Expense | B20: Chi phí thuế thu nhập doanh nghiệp | C20: 51 + 52 | D20: =Overall!C97+Overall!C98 -> 3739882570960 | E20: =Overall!D97+Overall!D98 -> 2846446729667 | F20: =Overall!E97+Overall!E98 -> 2581986910865 | G20: =Overall!F97+Overall!F98 -> 2787803957851
A21: Minority Interest | B21: Lợi ích cổ đông không kiểm soát | C21: 62 | D21: =IFERROR(INDEX(Overall!$A$81:$F$103, MATCH('Income Statement'!$C21,Overall!$A$81:$A$103,0), MATCH('Income Statement'!D$3,Overall!$A$80:$F$80,0)),"") -> 268075069713 | E21: =IFERROR(INDEX(Overall!$A$81:$F$103, MATCH('Income Statement'!$C21,Overall!$A$81:$A$103,0), MATCH('Income Statement'!E$3,Overall!$A$80:$F$80,0)),"") -> 187064832584 | F21: =IFERROR(INDEX(Overall!$A$81:$F$103, MATCH('Income Statement'!$C21,Overall!$A$81:$A$103,0), MATCH('Income Statement'!F$3,Overall!$A$80:$F$80,0)),"") -> 191750535785 | G21: =IFERROR(INDEX(Overall!$A$81:$F$103, MATCH('Income Statement'!$C21,Overall!$A$81:$A$103,0), MATCH('Income Statement'!G$3,Overall!$A$80:$F$80,0)),"") -> 157291314322
A22: Net Income From Continuing Ops | B22: Lợi nhuận sau thuế từ hoạt động liên tục | C22: 60 | D22: =IFERROR(INDEX(Overall!$A$81:$F$103, MATCH('Income Statement'!$C22,Overall!$A$81:$A$103,0), MATCH('Income Statement'!D$3,Overall!$A$80:$F$80,0)),"") -> 15066392289428 | E22: =IFERROR(INDEX(Overall!$A$81:$F$103, MATCH('Income Statement'!$C22,Overall!$A$81:$A$103,0), MATCH('Income Statement'!E$3,Overall!$A$80:$F$80,0)),"") -> 11793095479543 | F22: =IFERROR(INDEX(Overall!$A$81:$F$103, MATCH('Income Statement'!$C22,Overall!$A$81:$A$103,0), MATCH('Income Statement'!F$3,Overall!$A$80:$F$80,0)),"") -> 10590120585510 | G22: =IFERROR(INDEX(Overall!$A$81:$F$103, MATCH('Income Statement'!$C22,Overall!$A$81:$A$103,0), MATCH('Income Statement'!G$3,Overall!$A$80:$F$80,0)),"") -> 11571631226008
A23: Non-recurring Events | B23: Các khoản mục không thường xuyên | D23: =IFERROR(INDEX(Overall!$A$81:$F$103, MATCH('Income Statement'!$C23,Overall!$A$81:$A$103,0), MATCH('Income Statement'!D$3,Overall!$A$80:$F$80,0)),"") | E23: =IFERROR(INDEX(Overall!$A$81:$F$103, MATCH('Income Statement'!$C23,Overall!$A$81:$A$103,0), MATCH('Income Statement'!E$3,Overall!$A$80:$F$80,0)),"") | F23: =IFERROR(INDEX(Overall!$A$81:$F$103, MATCH('Income Statement'!$C23,Overall!$A$81:$A$103,0), MATCH('Income Statement'!F$3,Overall!$A$80:$F$80,0)),"") | G23: =IFERROR(INDEX(Overall!$A$81:$F$103, MATCH('Income Statement'!$C23,Overall!$A$81:$A$103,0), MATCH('Income Statement'!G$3,Overall!$A$80:$F$80,0)),"")
A24: Discontinued Operations | B24: Hoạt động đã ngừng kinh doanh | C24: 0 | D24: =IFERROR(INDEX(Overall!$A$81:$F$103, MATCH('Income Statement'!$C24,Overall!$A$81:$A$103,0), MATCH('Income Statement'!D$3,Overall!$A$80:$F$80,0)),"") | E24: =IFERROR(INDEX(Overall!$A$81:$F$103, MATCH('Income Statement'!$C24,Overall!$A$81:$A$103,0), MATCH('Income Statement'!E$3,Overall!$A$80:$F$80,0)),"") | F24: =IFERROR(INDEX(Overall!$A$81:$F$103, MATCH('Income Statement'!$C24,Overall!$A$81:$A$103,0), MATCH('Income Statement'!F$3,Overall!$A$80:$F$80,0)),"") | G24: =IFERROR(INDEX(Overall!$A$81:$F$103, MATCH('Income Statement'!$C24,Overall!$A$81:$A$103,0), MATCH('Income Statement'!G$3,Overall!$A$80:$F$80,0)),"")
A25: Extraordinary Items | B25: Các khoản mục bất thường | C25: 0 | D25: =IFERROR(INDEX(Overall!$A$81:$F$103, MATCH('Income Statement'!$C25,Overall!$A$81:$A$103,0), MATCH('Income Statement'!D$3,Overall!$A$80:$F$80,0)),"") | E25: =IFERROR(INDEX(Overall!$A$81:$F$103, MATCH('Income Statement'!$C25,Overall!$A$81:$A$103,0), MATCH('Income Statement'!E$3,Overall!$A$80:$F$80,0)),"") | F25: =IFERROR(INDEX(Overall!$A$81:$F$103, MATCH('Income Statement'!$C25,Overall!$A$81:$A$103,0), MATCH('Income Statement'!F$3,Overall!$A$80:$F$80,0)),"") | G25: =IFERROR(INDEX(Overall!$A$81:$F$103, MATCH('Income Statement'!$C25,Overall!$A$81:$A$103,0), MATCH('Income Statement'!G$3,Overall!$A$80:$F$80,0)),"")
A26: Effect Of Accounting Changes | B26: Ảnh hưởng của thay đổi chính sách kế toán | C26: 0 | D26: =IFERROR(INDEX(Overall!$A$81:$F$103, MATCH('Income Statement'!$C26,Overall!$A$81:$A$103,0), MATCH('Income Statement'!D$3,Overall!$A$80:$F$80,0)),"") | E26: =IFERROR(INDEX(Overall!$A$81:$F$103, MATCH('Income Statement'!$C26,Overall!$A$81:$A$103,0), MATCH('Income Statement'!E$3,Overall!$A$80:$F$80,0)),"") | F26: =IFERROR(INDEX(Overall!$A$81:$F$103, MATCH('Income Statement'!$C26,Overall!$A$81:$A$103,0), MATCH('Income Statement'!F$3,Overall!$A$80:$F$80,0)),"") | G26: =IFERROR(INDEX(Overall!$A$81:$F$103, MATCH('Income Statement'!$C26,Overall!$A$81:$A$103,0), MATCH('Income Statement'!G$3,Overall!$A$80:$F$80,0)),"")
A27: Other Items | B27: Các khoản mục khác | C27: 31 + 32 | D27: =Overall!C93+Overall!C94 -> 145549713902 | E27: =Overall!D93+Overall!D94 -> 46681283428 | F27: =Overall!E93+Overall!E94 -> 67511026277 | G27: =Overall!F93+Overall!F94 -> 135504154543
A28: Net Income | B28: Lợi nhuận sau thuế | C28: 60 | D28: =IFERROR(INDEX(Overall!$A$81:$F$103, MATCH('Income Statement'!$C28,Overall!$A$81:$A$103,0), MATCH('Income Statement'!D$3,Overall!$A$80:$F$80,0)),"") -> 15066392289428 | E28: =IFERROR(INDEX(Overall!$A$81:$F$103, MATCH('Income Statement'!$C28,Overall!$A$81:$A$103,0), MATCH('Income Statement'!E$3,Overall!$A$80:$F$80,0)),"") -> 11793095479543 | F28: =IFERROR(INDEX(Overall!$A$81:$F$103, MATCH('Income Statement'!$C28,Overall!$A$81:$A$103,0), MATCH('Income Statement'!F$3,Overall!$A$80:$F$80,0)),"") -> 10590120585510 | G28: =IFERROR(INDEX(Overall!$A$81:$F$103, MATCH('Income Statement'!$C28,Overall!$A$81:$A$103,0), MATCH('Income Statement'!G$3,Overall!$A$80:$F$80,0)),"") -> 11571631226008
A29: Preferred Stock And Other Adjustments | B29: Cổ tức cổ phiếu ưu đãi và các điều chỉnh khác | C29: 61 | D29: =IFERROR(INDEX(Overall!$A$81:$F$103, MATCH('Income Statement'!$C29,Overall!$A$81:$A$103,0), MATCH('Income Statement'!D$3,Overall!$A$80:$F$80,0)),"") -> 14798317219715 | E29: =IFERROR(INDEX(Overall!$A$81:$F$103, MATCH('Income Statement'!$C29,Overall!$A$81:$A$103,0), MATCH('Income Statement'!E$3,Overall!$A$80:$F$80,0)),"") -> 11606030646959 | F29: =IFERROR(INDEX(Overall!$A$81:$F$103, MATCH('Income Statement'!$C29,Overall!$A$81:$A$103,0), MATCH('Income Statement'!F$3,Overall!$A$80:$F$80,0)),"") -> 10398370049725 | G29: =IFERROR(INDEX(Overall!$A$81:$F$103, MATCH('Income Statement'!$C29,Overall!$A$81:$A$103,0), MATCH('Income Statement'!G$3,Overall!$A$80:$F$80,0)),"") -> 11414339911686
A30: Net Income Applicable To Common Shares | B30: Lợi nhuận phân bổ cho cổ đông phổ thông | D30: =IFERROR(INDEX(Overall!$A$81:$F$103, MATCH('Income Statement'!$C30,Overall!$A$81:$A$103,0), MATCH('Income Statement'!D$3,Overall!$A$80:$F$80,0)),"") | E30: =IFERROR(INDEX(Overall!$A$81:$F$103, MATCH('Income Statement'!$C30,Overall!$A$81:$A$103,0), MATCH('Income Statement'!E$3,Overall!$A$80:$F$80,0)),"") | F30: =IFERROR(INDEX(Overall!$A$81:$F$103, MATCH('Income Statement'!$C30,Overall!$A$81:$A$103,0), MATCH('Income Statement'!F$3,Overall!$A$80:$F$80,0)),"") | G30: =IFERROR(INDEX(Overall!$A$81:$F$103, MATCH('Income Statement'!$C30,Overall!$A$81:$A$103,0), MATCH('Income Statement'!G$3,Overall!$A$80:$F$80,0)),"")
A31: Effective Tax Rate | B31: Tỷ lệ thuế hiệu dụng | D31: =IFERROR(INDEX(Overall!$A$81:$F$103, MATCH('Income Statement'!$C31,Overall!$A$81:$A$103,0), MATCH('Income Statement'!D$3,Overall!$A$80:$F$80,0)),"") | E31: =IFERROR(INDEX(Overall!$A$81:$F$103, MATCH('Income Statement'!$C31,Overall!$A$81:$A$103,0), MATCH('Income Statement'!E$3,Overall!$A$80:$F$80,0)),"") | F31: =IFERROR(INDEX(Overall!$A$81:$F$103, MATCH('Income Statement'!$C31,Overall!$A$81:$A$103,0), MATCH('Income Statement'!F$3,Overall!$A$80:$F$80,0)),"") | G31: =IFERROR(INDEX(Overall!$A$81:$F$103, MATCH('Income Statement'!$C31,Overall!$A$81:$A$103,0), MATCH('Income Statement'!G$3,Overall!$A$80:$F$80,0)),"")
A32: Calculated Effective Tax Rate | B32: Tỷ lệ thuế hiệu dụng (tính toán) | D32: =IFERROR(INDEX(Overall!$A$81:$F$103, MATCH('Income Statement'!$C32,Overall!$A$81:$A$103,0), MATCH('Income Statement'!D$3,Overall!$A$80:$F$80,0)),"") | E32: =IFERROR(INDEX(Overall!$A$81:$F$103, MATCH('Income Statement'!$C32,Overall!$A$81:$A$103,0), MATCH('Income Statement'!E$3,Overall!$A$80:$F$80,0)),"") | F32: =IFERROR(INDEX(Overall!$A$81:$F$103, MATCH('Income Statement'!$C32,Overall!$A$81:$A$103,0), MATCH('Income Statement'!F$3,Overall!$A$80:$F$80,0)),"") | G32: =IFERROR(INDEX(Overall!$A$81:$F$103, MATCH('Income Statement'!$C32,Overall!$A$81:$A$103,0), MATCH('Income Statement'!G$3,Overall!$A$80:$F$80,0)),"")

Sheet Cashflow
A1: Cashflow
A2: All numbers in dong | B2: Tất cả số liệu tính theo đồng
C3: Mã số | D3: 2022 | E3: 2023 | F3: 2024 | G3: 2025
A4: Net Income | B4: Lợi nhuận sau thuế | C4: 1 | D4: ='Income Statement'!D28 -> 15066392289428 | E4: ='Income Statement'!E28 -> 11793095479543 | F4: ='Income Statement'!F28 -> 10590120585510 | G4: ='Income Statement'!G28 -> 11571631226008
A5: Operating Activities, Cash Flows Provided By or Used In | B5: Lưu chuyển tiền từ hoạt động kinh doanh | D5: =IFERROR(INDEX(Overall!$A$107:$F$136, MATCH(Cashflow!$C5,Overall!$A$107:$A$136,0), MATCH(Cashflow!D$3,Overall!$A$106:$F$106,0)),"") | E5: =IFERROR(INDEX(Overall!$A$107:$F$136, MATCH(Cashflow!$C5,Overall!$A$107:$A$136,0), MATCH(Cashflow!E$3,Overall!$A$106:$F$106,0)),"") | F5: =IFERROR(INDEX(Overall!$A$107:$F$136, MATCH(Cashflow!$C5,Overall!$A$107:$A$136,0), MATCH(Cashflow!F$3,Overall!$A$106:$F$106,0)),"") | G5: =IFERROR(INDEX(Overall!$A$107:$F$136, MATCH(Cashflow!$C5,Overall!$A$107:$A$136,0), MATCH(Cashflow!G$3,Overall!$A$106:$F$106,0)),"")
A6: Depreciation | B6: Khấu hao | C6: 2 | D6: =IFERROR(INDEX(Overall!$A$107:$F$136, MATCH(Cashflow!$C6,Overall!$A$107:$A$136,0), MATCH(Cashflow!D$3,Overall!$A$106:$F$106,0)),"") -> 3022954831285 | E6: =IFERROR(INDEX(Overall!$A$107:$F$136, MATCH(Cashflow!$C6,Overall!$A$107:$A$136,0), MATCH(Cashflow!E$3,Overall!$A$106:$F$106,0)),"") -> 3026921230677 | F6: =IFERROR(INDEX(Overall!$A$107:$F$136, MATCH(Cashflow!$C6,Overall!$A$107:$A$136,0), MATCH(Cashflow!F$3,Overall!$A$106:$F$106,0)),"") -> 2727709804035 | G6: =IFERROR(INDEX(Overall!$A$107:$F$136, MATCH(Cashflow!$C6,Overall!$A$107:$A$136,0), MATCH(Cashflow!G$3,Overall!$A$106:$F$106,0)),"") -> 2788367501746
A7: Adjustments To Net Income | B7: Điều chỉnh lợi nhuận | D7: =IFERROR(INDEX(Overall!$A$107:$F$136, MATCH(Cashflow!$C7,Overall!$A$107:$A$136,0), MATCH(Cashflow!D$3,Overall!$A$106:$F$106,0)),"") | E7: =IFERROR(INDEX(Overall!$A$107:$F$136, MATCH(Cashflow!$C7,Overall!$A$107:$A$136,0), MATCH(Cashflow!E$3,Overall!$A$106:$F$106,0)),"") | F7: =IFERROR(INDEX(Overall!$A$107:$F$136, MATCH(Cashflow!$C7,Overall!$A$107:$A$136,0), MATCH(Cashflow!F$3,Overall!$A$106:$F$106,0)),"") | G7: =IFERROR(INDEX(Overall!$A$107:$F$136, MATCH(Cashflow!$C7,Overall!$A$107:$A$136,0), MATCH(Cashflow!G$3,Overall!$A$106:$F$106,0)),"")
A8: Changes In Accounts Receivables | B8: Biến động các khoản phải thu | C8: 9 | D8: =IFERROR(INDEX(Overall!$A$107:$F$136, MATCH(Cashflow!$C8,Overall!$A$107:$A$136,0), MATCH(Cashflow!D$3,Overall!$A$106:$F$106,0)),"") -> 782276386743 | E8: =IFERROR(INDEX(Overall!$A$107:$F$136, MATCH(Cashflow!$C8,Overall!$A$107:$A$136,0), MATCH(Cashflow!E$3,Overall!$A$106:$F$106,0)),"") -> -550297452099 | F8: =IFERROR(INDEX(Overall!$A$107:$F$136, MATCH(Cashflow!$C8,Overall!$A$107:$A$136,0), MATCH(Cashflow!F$3,Overall!$A$106:$F$106,0)),"") -> 4549384677628 | G8: =IFERROR(INDEX(Overall!$A$107:$F$136, MATCH(Cashflow!$C8,Overall!$A$107:$A$136,0), MATCH(Cashflow!G$3,Overall!$A$106:$F$106,0)),"") -> -6623511061086
A9: Changes In Liabilities | B9: Biến động các khoản phải trả | C9: 11 | D9: =IFERROR(INDEX(Overall!$A$107:$F$136, MATCH(Cashflow!$C9,Overall!$A$107:$A$136,0), MATCH(Cashflow!D$3,Overall!$A$106:$F$106,0)),"") -> -3677892636800 | E9: =IFERROR(INDEX(Overall!$A$107:$F$136, MATCH(Cashflow!$C9,Overall!$A$107:$A$136,0), MATCH(Cashflow!E$3,Overall!$A$106:$F$106,0)),"") -> 1159357930370 | F9: =IFERROR(INDEX(Overall!$A$107:$F$136, MATCH(Cashflow!$C9,Overall!$A$107:$A$136,0), MATCH(Cashflow!F$3,Overall!$A$106:$F$106,0)),"") -> 930606432959 | G9: =IFERROR(INDEX(Overall!$A$107:$F$136, MATCH(Cashflow!$C9,Overall!$A$107:$A$136,0), MATCH(Cashflow!G$3,Overall!$A$106:$F$106,0)),"") -> 6352615685034
A10: Changes In Inventories | B10: Biến động hàng tồn kho | C10: 10 | D10: =IFERROR(INDEX(Overall!$A$107:$F$136, MATCH(Cashflow!$C10,Overall!$A$107:$A$136,0), MATCH(Cashflow!D$3,Overall!$A$106:$F$106,0)),"") -> -680659726216 | E10: =IFERROR(INDEX(Overall!$A$107:$F$136, MATCH(Cashflow!$C10,Overall!$A$107:$A$136,0), MATCH(Cashflow!E$3,Overall!$A$106:$F$106,0)),"") -> 115462821548 | F10: =IFERROR(INDEX(Overall!$A$107:$F$136, MATCH(Cashflow!$C10,Overall!$A$107:$A$136,0), MATCH(Cashflow!F$3,Overall!$A$106:$F$106,0)),"") -> -662132189021 | G10: =IFERROR(INDEX(Overall!$A$107:$F$136, MATCH(Cashflow!$C10,Overall!$A$107:$A$136,0), MATCH(Cashflow!G$3,Overall!$A$106:$F$106,0)),"") -> 144482427857
A11: Changes In Other Operating Activities | B11: Biến động các khoản mục hoạt động khác | C11: 17 | D11: =IFERROR(INDEX(Overall!$A$107:$F$136, MATCH(Cashflow!$C11,Overall!$A$107:$A$136,0), MATCH(Cashflow!D$3,Overall!$A$106:$F$106,0)),"") -> -545607495656 | E11: =IFERROR(INDEX(Overall!$A$107:$F$136, MATCH(Cashflow!$C11,Overall!$A$107:$A$136,0), MATCH(Cashflow!E$3,Overall!$A$106:$F$106,0)),"") -> -238889627322 | F11: =IFERROR(INDEX(Overall!$A$107:$F$136, MATCH(Cashflow!$C11,Overall!$A$107:$A$136,0), MATCH(Cashflow!F$3,Overall!$A$106:$F$106,0)),"") -> -362716748314 | G11: =IFERROR(INDEX(Overall!$A$107:$F$136, MATCH(Cashflow!$C11,Overall!$A$107:$A$136,0), MATCH(Cashflow!G$3,Overall!$A$106:$F$106,0)),"") -> -348783972396
A12: Total Cash Flow From Operating Activities | B12: Lưu chuyển tiền thuần từ hoạt động kinh doanh | C12: 20 | D12: =IFERROR(INDEX(Overall!$A$107:$F$136, MATCH(Cashflow!$C12,Overall!$A$107:$A$136,0), MATCH(Cashflow!D$3,Overall!$A$106:$F$106,0)),"") -> 12792070499188 | E12: =IFERROR(INDEX(Overall!$A$107:$F$136, MATCH(Cashflow!$C12,Overall!$A$107:$A$136,0), MATCH(Cashflow!E$3,Overall!$A$106:$F$106,0)),"") -> 13827044652491 | F12: =IFERROR(INDEX(Overall!$A$107:$F$136, MATCH(Cashflow!$C12,Overall!$A$107:$A$136,0), MATCH(Cashflow!F$3,Overall!$A$106:$F$106,0)),"") -> 9035210701364 | G12: =IFERROR(INDEX(Overall!$A$107:$F$136, MATCH(Cashflow!$C12,Overall!$A$107:$A$136,0), MATCH(Cashflow!G$3,Overall!$A$106:$F$106,0)),"") -> 13040237870138
A13: Investing Activities, Cash Flows Provided By | B13: Lưu chuyển tiền từ hoạt động đầu tư | D13: =IFERROR(INDEX(Overall!$A$107:$F$136, MATCH(Cashflow!$C13,Overall!$A$107:$A$136,0), MATCH(Cashflow!D$3,Overall!$A$106:$F$106,0)),"") | E13: =IFERROR(INDEX(Overall!$A$107:$F$136, MATCH(Cashflow!$C13,Overall!$A$107:$A$136,0), MATCH(Cashflow!E$3,Overall!$A$106:$F$106,0)),"") | F13: =IFERROR(INDEX(Overall!$A$107:$F$136, MATCH(Cashflow!$C13,Overall!$A$107:$A$136,0), MATCH(Cashflow!F$3,Overall!$A$106:$F$106,0)),"") | G13: =IFERROR(INDEX(Overall!$A$107:$F$136, MATCH(Cashflow!$C13,Overall!$A$107:$A$136,0), MATCH(Cashflow!G$3,Overall!$A$106:$F$106,0)),"")
A14: Capital Expenditures | B14: Chi đầu tư tài sản cố định (CAPEX) | C14: 21 | D14: =IFERROR(INDEX(Overall!$A$107:$F$136, MATCH(Cashflow!$C14,Overall!$A$107:$A$136,0), MATCH(Cashflow!D$3,Overall!$A$106:$F$106,0)),"") -> -2009673196429 | E14: =IFERROR(INDEX(Overall!$A$107:$F$136, MATCH(Cashflow!$C14,Overall!$A$107:$A$136,0), MATCH(Cashflow!E$3,Overall!$A$106:$F$106,0)),"") -> -1841341777865 | F14: =IFERROR(INDEX(Overall!$A$107:$F$136, MATCH(Cashflow!$C14,Overall!$A$107:$A$136,0), MATCH(Cashflow!F$3,Overall!$A$106:$F$106,0)),"") -> -1925456571752 | G14: =IFERROR(INDEX(Overall!$A$107:$F$136, MATCH(Cashflow!$C14,Overall!$A$107:$A$136,0), MATCH(Cashflow!G$3,Overall!$A$106:$F$106,0)),"") -> -2314735009692
A15: Investments | B15: Đầu tư tài chính | C15: 22 | D15: =IFERROR(INDEX(Overall!$A$107:$F$136, MATCH(Cashflow!$C15,Overall!$A$107:$A$136,0), MATCH(Cashflow!D$3,Overall!$A$106:$F$106,0)),"") -> 570658941 | E15: =IFERROR(INDEX(Overall!$A$107:$F$136, MATCH(Cashflow!$C15,Overall!$A$107:$A$136,0), MATCH(Cashflow!E$3,Overall!$A$106:$F$106,0)),"") -> 66000000 | F15: =IFERROR(INDEX(Overall!$A$107:$F$136, MATCH(Cashflow!$C15,Overall!$A$107:$A$136,0), MATCH(Cashflow!F$3,Overall!$A$106:$F$106,0)),"") -> 386025703 | G15: =IFERROR(INDEX(Overall!$A$107:$F$136, MATCH(Cashflow!$C15,Overall!$A$107:$A$136,0), MATCH(Cashflow!G$3,Overall!$A$106:$F$106,0)),"") -> 632543704
A16: Other Cash flows from Investing Activities | B16: Lưu chuyển tiền khác từ hoạt động đầu tư | C16: 23 | D16: =IFERROR(INDEX(Overall!$A$107:$F$136, MATCH(Cashflow!$C16,Overall!$A$107:$A$136,0), MATCH(Cashflow!D$3,Overall!$A$106:$F$106,0)),"") -> -40741761303346 | E16: =IFERROR(INDEX(Overall!$A$107:$F$136, MATCH(Cashflow!$C16,Overall!$A$107:$A$136,0), MATCH(Cashflow!E$3,Overall!$A$106:$F$106,0)),"") -> -50078274935445 | F16: =IFERROR(INDEX(Overall!$A$107:$F$136, MATCH(Cashflow!$C16,Overall!$A$107:$A$136,0), MATCH(Cashflow!F$3,Overall!$A$106:$F$106,0)),"") -> -46644494787639 | G16: =IFERROR(INDEX(Overall!$A$107:$F$136, MATCH(Cashflow!$C16,Overall!$A$107:$A$136,0), MATCH(Cashflow!G$3,Overall!$A$106:$F$106,0)),"") -> -45592159986135
A17: Total Cash Flows From Investing Activities | B17: Lưu chuyển tiền thuần từ hoạt động đầu tư | C17: 30 | D17: =IFERROR(INDEX(Overall!$A$107:$F$136, MATCH(Cashflow!$C17,Overall!$A$107:$A$136,0), MATCH(Cashflow!D$3,Overall!$A$106:$F$106,0)),"") -> 265039541155 | E17: =IFERROR(INDEX(Overall!$A$107:$F$136, MATCH(Cashflow!$C17,Overall!$A$107:$A$136,0), MATCH(Cashflow!E$3,Overall!$A$106:$F$106,0)),"") -> -11248693693022 | F17: =IFERROR(INDEX(Overall!$A$107:$F$136, MATCH(Cashflow!$C17,Overall!$A$107:$A$136,0), MATCH(Cashflow!F$3,Overall!$A$106:$F$106,0)),"") -> 7468309783967 | G17: =IFERROR(INDEX(Overall!$A$107:$F$136, MATCH(Cashflow!$C17,Overall!$A$107:$A$136,0), MATCH(Cashflow!G$3,Overall!$A$106:$F$106,0)),"") -> -6468619501015
A18: Financing Activities, Cash Flows Provided By | B18: Lưu chuyển tiền từ hoạt động tài chính | D18: =IFERROR(INDEX(Overall!$A$107:$F$136, MATCH(Cashflow!$C18,Overall!$A$107:$A$136,0), MATCH(Cashflow!D$3,Overall!$A$106:$F$106,0)),"") | E18: =IFERROR(INDEX(Overall!$A$107:$F$136, MATCH(Cashflow!$C18,Overall!$A$107:$A$136,0), MATCH(Cashflow!E$3,Overall!$A$106:$F$106,0)),"") | F18: =IFERROR(INDEX(Overall!$A$107:$F$136, MATCH(Cashflow!$C18,Overall!$A$107:$A$136,0), MATCH(Cashflow!F$3,Overall!$A$106:$F$106,0)),"") | G18: =IFERROR(INDEX(Overall!$A$107:$F$136, MATCH(Cashflow!$C18,Overall!$A$107:$A$136,0), MATCH(Cashflow!G$3,Overall!$A$106:$F$106,0)),"")
A19: Dividends Paid | B19: Cổ tức đã trả | C19: 36 | D19: =IFERROR(INDEX(Overall!$A$107:$F$136, MATCH(Cashflow!$C19,Overall!$A$107:$A$136,0), MATCH(Cashflow!D$3,Overall!$A$106:$F$106,0)),"") -> -5882313058641 | E19: =IFERROR(INDEX(Overall!$A$107:$F$136, MATCH(Cashflow!$C19,Overall!$A$107:$A$136,0), MATCH(Cashflow!E$3,Overall!$A$106:$F$106,0)),"") -> -7119780163201 | F19: =IFERROR(INDEX(Overall!$A$107:$F$136, MATCH(Cashflow!$C19,Overall!$A$107:$A$136,0), MATCH(Cashflow!F$3,Overall!$A$106:$F$106,0)),"") -> -13872476202356 | G19: =IFERROR(INDEX(Overall!$A$107:$F$136, MATCH(Cashflow!$C19,Overall!$A$107:$A$136,0), MATCH(Cashflow!G$3,Overall!$A$106:$F$106,0)),"") -> -5011650250256
A20: Sale Purchase of Stock | B20: Mua/bán cổ phiếu | C20: 31 | D20: =IFERROR(INDEX(Overall!$A$107:$F$136, MATCH(Cashflow!$C20,Overall!$A$107:$A$136,0), MATCH(Cashflow!D$3,Overall!$A$106:$F$106,0)),"") -> 118345978175 | E20: =IFERROR(INDEX(Overall!$A$107:$F$136, MATCH(Cashflow!$C20,Overall!$A$107:$A$136,0), MATCH(Cashflow!E$3,Overall!$A$106:$F$106,0)),"") -> - | F20: =IFERROR(INDEX(Overall!$A$107:$F$136, MATCH(Cashflow!$C20,Overall!$A$107:$A$136,0), MATCH(Cashflow!F$3,Overall!$A$106:$F$106,0)),"") -> 0 | G20: =IFERROR(INDEX(Overall!$A$107:$F$136, MATCH(Cashflow!$C20,Overall!$A$107:$A$136,0), MATCH(Cashflow!G$3,Overall!$A$106:$F$106,0)),"") -> 0
A21: Net Borrowings | B21: Vay nợ ròng | C21: 33 | D21: =IFERROR(INDEX(Overall!$A$107:$F$136, MATCH(Cashflow!$C21,Overall!$A$107:$A$136,0), MATCH(Cashflow!D$3,Overall!$A$106:$F$106,0)),"") -> 1325381539466 | E21: =IFERROR(INDEX(Overall!$A$107:$F$136, MATCH(Cashflow!$C21,Overall!$A$107:$A$136,0), MATCH(Cashflow!E$3,Overall!$A$106:$F$106,0)),"") -> 2075745608357 | F21: =IFERROR(INDEX(Overall!$A$107:$F$136, MATCH(Cashflow!$C21,Overall!$A$107:$A$136,0), MATCH(Cashflow!F$3,Overall!$A$106:$F$106,0)),"") -> 1803899835850 | G21: =IFERROR(INDEX(Overall!$A$107:$F$136, MATCH(Cashflow!$C21,Overall!$A$107:$A$136,0), MATCH(Cashflow!G$3,Overall!$A$106:$F$106,0)),"") -> 1108894654657
